Workbook

Sheet Decks
A1: Deck | B1: Deck type | C1: Linked season of life | D1: Description | E1: Minimum cards | F1: Cards written | G1: Ready to publish? | H1: Disclaimer shown on deck
A2: Somewhere in Between | B2: Monthly or library | D2: Where you started, where you are, and everything you’re carrying in between. | E2: 31 | F2: =COUNTIF(Cards!$A:$A,A2) -> 74 | G2: =IF(F2>=E2,"Ready","Needs more") -> Ready
A3: Let It Fall (October 2026) | B3: Monthly | D3: What to release, what to keep, and what to carry into slower days. | E3: 31 | F3: =COUNTIF(Cards!$A:$A,A3) -> 31 | G3: =IF(F3>=E3,"Ready","Needs more") -> Ready
A4: Starting over | B4: Life-season | C4: Starting over | D4: For the blank page after something ends, and the courage it takes to write on it. | E4: 10 | F4: =COUNTIF(Cards!$A:$A,A4) -> 12 | G4: =IF(F4>=E4,"Ready","Needs more") -> Ready
A5: In a transition | B5: Life-season | C5: In a transition | D5: For the in-between, when you’ve left one version of your life and haven’t landed in the next. | E5: 10 | F5: =COUNTIF(Cards!$A:$A,A5) -> 12 | G5: =IF(F5>=E5,"Ready","Needs more") -> Ready
A6: Healing my heart | B6: Life-season | C6: Healing my heart | D6: For the ache after it ends, and finding your way back to yourself. | E6: 10 | F6: =COUNTIF(Cards!$A:$A,A6) -> 12 | G6: =IF(F6>=E6,"Ready","Needs more") -> Ready
A7: Grieving something | B7: Life-season | C7: Grieving something | D7: For missing someone or something, and learning to carry it with you. | E7: 10 | F7: =COUNTIF(Cards!$A:$A,A7) -> 12 | G7: =IF(F7>=E7,"Ready","Needs more") -> Ready
A8: Running on empty | B8: Life-season | C8: Running on empty | D8: For when you’ve been giving more than you have. Time to refill. | E8: 10 | F8: =COUNTIF(Cards!$A:$A,A8) -> 12 | G8: =IF(F8>=E8,"Ready","Needs more") -> Ready
A9: Building something | B9: Life-season | C9: Building something | D9: For the ones making something from nothing, and everything it asks of you. | E9: 10 | F9: =COUNTIF(Cards!$A:$A,A9) -> 12 | G9: =IF(F9>=E9,"Ready","Needs more") -> Ready
A10: Falling in love | B10: Life-season | C10: Falling in love | D10: For letting someone in, and staying yourself while you do. | E10: 10 | F10: =COUNTIF(Cards!$A:$A,A10) -> 12 | G10: =IF(F10>=E10,"Ready","Needs more") -> Ready
A11: Becoming a mom | B11: Life-season | C11: Becoming a mom | D11: For becoming someone new without losing who you were. | E11: 10 | F11: =COUNTIF(Cards!$A:$A,A11) -> 12 | G11: =IF(F11>=E11,"Ready","Needs more") -> Ready
A12: Figuring it out | B12: Life-season | C12: Figuring it out | D12: For not knowing yet, and being okay with it. | E12: 10 | F12: =COUNTIF(Cards!$A:$A,A12) -> 12 | G12: =IF(F12>=E12,"Ready","Needs more") -> Ready
A13: Listening to my body | B13: Body | D13: Tune in to what your body has been telling you all along. | E13: 10 | F13: =COUNTIF(Cards!$A:$A,A13) -> 12 | G13: =IF(F13>=E13,"Ready","Needs more") -> Ready | H13: These questions are for reflection, not medical advice.
A14: My cycle | B14: Body | D14: How your month actually feels, and the patterns hiding in plain sight. | E14: 10 | F14: =COUNTIF(Cards!$A:$A,A14) -> 12 | G14: =IF(F14>=E14,"Ready","Needs more") -> Ready | H14: These questions are for reflection, not medical advice.
A15: Perimenopause and beyond | B15: Body | D15: A changing body, a changing you, and what you want from this chapter. | E15: 10 | F15: =COUNTIF(Cards!$A:$A,A15) -> 12 | G15: =IF(F15>=E15,"Ready","Needs more") -> Ready | H15: These questions are for reflection, not medical advice.
A16: After baby | B16: Body | D16: Meeting your body, and yourself, all over again. | E16: 10 | F16: =COUNTIF(Cards!$A:$A,A16) -> 12 | G16: =IF(F16>=E16,"Ready","Needs more") -> Ready | H16: These questions are for reflection, not medical advice.
A17: Looking for answers | B17: Body | D17: For when something feels off and you’re still connecting the dots. | E17: 10 | F17: =COUNTIF(Cards!$A:$A,A17) -> 12 | G17: =IF(F17>=E17,"Ready","Needs more") -> Ready | H17: These questions are for reflection, not medical advice.
A18: Energy and rhythm | B18: Body | D18: When you feel most like yourself, what drains you, and what fills you back up. | E18: 10 | F18: =COUNTIF(Cards!$A:$A,A18) -> 12 | G18: =IF(F18>=E18,"Ready","Needs more") -> Ready | H18: These questions are for reflection, not medical advice.
A20: Total cards | F20: =SUM(F2:F18) -> 285
A21: Season with no deck: “Just checking in” uses the current monthly deck.
A22: How to review: add comments in the yellow “Your notes” column on the Cards tab. Minimums come from the PRD (monthly 31, life-season and Body 10).

Sheet Cards
A1: Deck | B1: Deck type | C1: Category | D1: Question | E1: Status | F1: Original wording | G1: Your notes
A2: Somewhere in Between | B2: Monthly or library | C2: Where You Started | D2: What’s one thing you believed about yourself a year ago that you don’t believe anymore? | E2: Rewritten | F2: What’s one thing you believed about yourself in January that you don’t believe anymore?
A3: Somewhere in Between | B3: Monthly or library | C3: Where You Started | D3: What did this past season teach you that you didn’t ask to learn? | E3: Rewritten | F3: What did this summer teach you that you didn’t ask to learn?
A4: Somewhere in Between | B4: Monthly or library | C4: Where You Started | D4: What’s a recent version of you that you’re proud of? | E4: Rewritten | F4: What’s a version of you from earlier this year you’re proud of?
A5: Somewhere in Between | B5: Monthly or library | C5: Where You Started | D5: What’s something you said yes to recently that you’d say no to now? | E5: Rewritten | F5: What’s something you said yes to this year that you’d say no to now?
A6: Somewhere in Between | B6: Monthly or library | C6: Where You Started | D6: What surprised you most about yourself lately? | E6: Rewritten | F6: What surprised you most about yourself this year?
A7: Somewhere in Between | B7: Monthly or library | C7: Where You Started | D7: What’s a risk you took recently, big or small? | E7: Rewritten | F7: What’s a risk you took this year, big or small?
A8: Somewhere in Between | B8: Monthly or library | C8: Where You Started | D8: What’s something you used to need that you don’t need anymore? | E8: Original
A9: Somewhere in Between | B9: Monthly or library | C9: Where You Started | D9: What’s the hardest thing you’ve done lately that no one really saw? | E9: Rewritten | F9: What’s the hardest thing you did this year that no one really saw?
A10: Somewhere in Between | B10: Monthly or library | C10: Where You Started | D10: What’s something you built this past year, literally or otherwise? | E10: Rewritten | F10: What’s something you built this year, literally or otherwise?
A11: Somewhere in Between | B11: Monthly or library | C11: Where You Started | D11: What’s a goal you quietly let go of, and how do you feel about that now? | E11: Original
A12: Somewhere in Between | B12: Monthly or library | C12: Where You Are | D12: What are you in the middle of right now that no one’s asking you about? | E12: Original
A13: Somewhere in Between | B13: Monthly or library | C13: Where You Are | D13: What does “figuring it out” look like for you right now? | E13: Original
A14: Somewhere in Between | B14: Monthly or library | C14: Where You Are | D14: What’s something you’re doing right that you don’t give yourself credit for? | E14: Original
A15: Somewhere in Between | B15: Monthly or library | C15: Where You Are | D15: What’s a question you’re currently living inside of? | E15: Original
A16: Somewhere in Between | B16: Monthly or library | C16: Where You Are | D16: What’s true for you now that wasn’t true six months ago? | E16: Original
A17: Somewhere in Between | B17: Monthly or library | C17: Where You Are | D17: What’s something you’re pretending to have figured out? | E17: Original
A18: Somewhere in Between | B18: Monthly or library | C18: Where You Are | D18: Where do you feel most like yourself these days? | E18: Original
A19: Somewhere in Between | B19: Monthly or library | C19: Where You Are | D19: What’s a small thing that’s been steadying you lately? | E19: Original
A20: Somewhere in Between | B20: Monthly or library | C20: Where You Are | D20: What’s the last thing that made you feel completely present? | E20: Original
A21: Somewhere in Between | B21: Monthly or library | C21: Where You Are | D21: What part of your life feels most “in progress” right now? | E21: Original
A22: Somewhere in Between | B22: Monthly or library | C22: Where You Are | D22: What’s something you’re curious about but haven’t pursued? | E22: Original
... A31: Somewhere in Between | B31: Monthly or library | C31: What You're Carrying | D31: What’s something you’re tired of being strong about? | E31: Original
A32: Somewhere in Between | B32: Monthly or library | C32: What You're Carrying | D32: What weight would you like to set down before this season ends? | E32: Rewritten | F32: What weight would you like to set down before the year ends?
A33: Somewhere in Between | B33: Monthly or library | C33: What You're Carrying | D33: What are you carrying with you from this past season that you want to keep? | E33: Rewritten | F33: What are you carrying with you from this summer that you want to keep?
A34: Somewhere in Between | B34: Monthly or library | C34: What You're Carrying | D34: What lesson are you taking into the next season? | E34: Original
A35: Somewhere in Between | B35: Monthly or library | C35: What You're Carrying | D35: What’s taking up more space in your head than it deserves? | E35: Original
A36: Somewhere in Between | B36: Monthly or library | C36: What You're Carrying | D36: What are you holding onto because it still feels good, not because you have to? | E36: Original
A37: Somewhere in Between | B37: Monthly or library | C37: What's Next | D37: What do you want to do with the next few months? | E37: Rewritten | F37: What are you doing with the rest of this year?
A38: Somewhere in Between | B38: Monthly or library | C38: What's Next | D38: What’s one thing you want to be true about your life a year from now? | E38: Rewritten | F38: What’s one thing you want to be true about your life by December 31?
A39: Somewhere in Between | B39: Monthly or library | C39: What's Next | D39: What’s a version of yourself you’re growing into? | E39: Original
A40: Somewhere in Between | B40: Monthly or library | C40: What's Next | D40: What do you want more of in the next three months? | E40: Original
A41: Somewhere in Between | B41: Monthly or library | C41: What's Next | D41: If this next season had a theme, what would you want it to be? | E41: Original
A42: Somewhere in Between | B42: Monthly or library | C42: What's Next | D42: What’s something you want to say yes to that you’ve been avoiding? | E42: Original
A43: Somewhere in Between | B43: Monthly or library | C43: What's Next | D43: What’s something small you can do this week that your future self will thank you for? | E43: Original
A44: Somewhere in Between | B44: Monthly or library | C44: What's Next | D44: What’s a version of rest you actually want to practice? | E44: Original
A45: Somewhere in Between | B45: Monthly or library | C45: What's Next | D45: What’s something you’re excited about that you haven’t told many people? | E45: Original
A46: Somewhere in Between | B46: Monthly or library | C46: What's Next | D46: What do you want to protect in the months ahead? | E46: Rewritten | F46: What do you want to protect for the rest of this year?
A47: Somewhere in Between | B47: Monthly or library | C47: What's Next | D47: If you trusted yourself completely, what would you do differently right now? | E47: Original
A48: Somewhere in Between | B48: Monthly or library | C48: What's Next | D48: What would make the next few months feel good, not just productive? | E48: Rewritten | F48: What would make the rest of this year feel good, not just productive?
...
